{"cells": [{"metadata": {}, "cell_type": "code", "source": "\nimport os, types\nimport pandas as pd\nfrom botocore.client import Config\nimport ibm_boto3\n\ndef __iter__(self): return 0\n\n# @hidden_cell\n# The following code accesses a file in your IBM Cloud Object Storage. It includes your credentials.\n# You might want to remove those credentials before you share the notebook.\nclient_03ac84cdc3bc4eaa9d86485ecd9b4d65 = ibm_boto3.client(service_name='s3',\n    ibm_api_key_id='Y8XltIqCRiOdnu3KAZWK2j_JGf6lVH0EMQtdPkuEwdnK',\n    ibm_auth_endpoint=\"https://iam.cloud.ibm.com/oidc/token\",\n    config=Config(signature_version='oauth'),\n    endpoint_url='https://s3.private.us.cloud-object-storage.appdomain.cloud')\n\nstreaming_body_1 = client_03ac84cdc3bc4eaa9d86485ecd9b4d65.get_object(Bucket='fertilizersrecommendationsystemfo-donotdelete-pr-4stzrjkbijajdm', Key='Fertilizers_Recommendation_ System_For_Disease_ Prediction.zip')['Body']\n\n# Your data file was loaded into a botocore.response.StreamingBody object.\n# Please read the documentation of ibm_boto3 and pandas to learn more about the possibilities to load the data.\n# ibm_boto3 documentation: https://ibm.github.io/ibm-cos-sdk-python/\n# pandas documentation: http://pandas.pydata.org/\n", "execution_count": 1, "outputs": []}, {"metadata": {}, "cell_type": "code", "source": "ls", "execution_count": 2, "outputs": [{"output_type": "stream", "text": "\u001b[0m\u001b[01;34m'Dataset Plant Disease'\u001b[0m/\r\n", "name": "stdout"}]}, {"metadata": {}, "cell_type": "code", "source": "from io import BytesIO\nimport zipfile\nunzip=zipfile.ZipFile(BytesIO(streaming_body_1.read()),'r')\nfile_paths=unzip.namelist()\nfor path in file_paths:\n    unzip.extract(path)", "execution_count": 3, "outputs": []}, {"metadata": {}, "cell_type": "code", "source": "pwd", "execution_count": 4, "outputs": [{"output_type": "execute_result", "execution_count": 4, "data": {"text/plain": "'/home/wsuser/work'"}, "metadata": {}}]}, {"metadata": {}, "cell_type": "code", "source": "from tensorflow.keras.preprocessing.image import ImageDataGenerator\n\ntrain_datagen=ImageDataGenerator(rescale=1./255,zoom_range=0.2,horizontal_flip=True,vertical_flip=False)\n\ntest_datagen=ImageDataGenerator(rescale=1./255)", "execution_count": 5, "outputs": []}, {"metadata": {}, "cell_type": "code", "source": "x_train=train_datagen.flow_from_directory(r\"/home/wsuser/work/Dataset Plant Disease/fruit-dataset/fruit-dataset/train\",target_size=(64,64),\n                                        class_mode='categorical',batch_size=24)", "execution_count": 6, "outputs": [{"output_type": "stream", "text": "Found 5384 images belonging to 6 classes.\n", "name": "stdout"}]}, {"metadata": {}, "cell_type": "code", "source": "x_test=test_datagen.flow_from_directory(r\"/home/wsuser/work/Dataset Plant Disease/fruit-dataset/fruit-dataset/test\",target_size=(64,64),\n                                        class_mode='categorical',batch_size=24)\n\nx_train.class_indices", "execution_count": 7, "outputs": [{"output_type": "stream", "text": "Found 1686 images belonging to 6 classes.\n", "name": "stdout"}, {"output_type": "execute_result", "execution_count": 7, "data": {"text/plain": "{'Apple___Black_rot': 0,\n 'Apple___healthy': 1,\n 'Corn_(maize)___Northern_Leaf_Blight': 2,\n 'Corn_(maize)___healthy': 3,\n 'Peach___Bacterial_spot': 4,\n 'Peach___healthy': 5}"}, "metadata": {}}]}, {"metadata": {}, "cell_type": "code", "source": "from tensorflow.keras.models import Sequential\nfrom tensorflow.keras.layers import Dense,Convolution2D,MaxPooling2D,Flatten\n", "execution_count": 8, "outputs": []}, {"metadata": {}, "cell_type": "code", "source": "model=Sequential()", "execution_count": 9, "outputs": []}, {"metadata": {}, "cell_type": "code", "source": "model.add(Convolution2D(32,(3,3),input_shape=(64,64,3),activation='relu'))\n", "execution_count": 10, "outputs": []}, {"metadata": {}, "cell_type": "code", "source": "\nmodel.add(MaxPooling2D(pool_size=(2,2)))\n\nmodel.add(Flatten())\n\nmodel.summary()", "execution_count": 11, "outputs": [{"output_type": "stream", "text": "Model: \"sequential\"\n_________________________________________________________________\n Layer (type)                Output Shape              Param #   \n=================================================================\n conv2d (Conv2D)             (None, 62, 62, 32)        896       \n                                                                 \n max_pooling2d (MaxPooling2D  (None, 31, 31, 32)       0         \n )                                                               \n                                                                 \n flatten (Flatten)           (None, 30752)             0         \n                                                                 \n=================================================================\nTotal params: 896\nTrainable params: 896\nNon-trainable params: 0\n_________________________________________________________________\n", "name": "stdout"}]}, {"metadata": {}, "cell_type": "code", "source": "model.add(Dense(300,activation='relu'))\nmodel.add(Dense(150,activation='relu'))", "execution_count": 12, "outputs": []}, {"metadata": {}, "cell_type": "code", "source": "model.add(Dense(6,activation='softmax'))\n\nmodel.compile(loss='categorical_crossentropy',optimizer='adam',metrics=['accuracy'])\n\nlen(x_train)", "execution_count": 13, "outputs": [{"output_type": "execute_result", "execution_count": 13, "data": {"text/plain": "225"}, "metadata": {}}]}, {"metadata": {}, "cell_type": "code", "source": "model.fit_generator(x_train,steps_per_epoch=len(x_train),validation_data=x_test,validation_steps=len(x_test),epochs=10)", "execution_count": 14, "outputs": [{"output_type": "stream", "text": "/tmp/wsuser/ipykernel_280/1582812018.py:1: UserWarning: `Model.fit_generator` is deprecated and will be removed in a future version. Please use `Model.fit`, which supports generators.\n  model.fit_generator(x_train,steps_per_epoch=len(x_train),validation_data=x_test,validation_steps=len(x_test),epochs=10)\n", "name": "stderr"}, {"output_type": "stream", "text": "Epoch 1/10\n225/225 [==============================] - 33s 146ms/step - loss: 0.5315 - accuracy: 0.8113 - val_loss: 0.2836 - val_accuracy: 0.8944\nEpoch 2/10\n225/225 [==============================] - 32s 140ms/step - loss: 0.2595 - accuracy: 0.9069 - val_loss: 0.2284 - val_accuracy: 0.9104\nEpoch 3/10\n225/225 [==============================] - 31s 137ms/step - loss: 0.1853 - accuracy: 0.9352 - val_loss: 0.1298 - val_accuracy: 0.9549\nEpoch 4/10\n225/225 [==============================] - 30s 134ms/step - loss: 0.1679 - accuracy: 0.9411 - val_loss: 0.1360 - val_accuracy: 0.9549\nEpoch 5/10\n225/225 [==============================] - 31s 138ms/step - loss: 0.1457 - accuracy: 0.9473 - val_loss: 0.1860 - val_accuracy: 0.9276\nEpoch 6/10\n225/225 [==============================] - 31s 139ms/step - loss: 0.1160 - accuracy: 0.9584 - val_loss: 0.1014 - val_accuracy: 0.9668\nEpoch 7/10\n225/225 [==============================] - 31s 136ms/step - loss: 0.0941 - accuracy: 0.9656 - val_loss: 0.1703 - val_accuracy: 0.9520\nEpoch 8/10\n225/225 [==============================] - 30s 135ms/step - loss: 0.1080 - accuracy: 0.9645 - val_loss: 0.1427 - val_accuracy: 0.9579\nEpoch 9/10\n225/225 [==============================] - 31s 136ms/step - loss: 0.0929 - accuracy: 0.9653 - val_loss: 0.1395 - val_accuracy: 0.9614\nEpoch 10/10\n225/225 [==============================] - 30s 134ms/step - loss: 0.0745 - accuracy: 0.9751 - val_loss: 0.0941 - val_accuracy: 0.9644\n", "name": "stdout"}, {"output_type": "execute_result", "execution_count": 14, "data": {"text/plain": "<keras.callbacks.History at 0x7f79e96dc700>"}, "metadata": {}}]}, {"metadata": {}, "cell_type": "code", "source": "model.save('fruit.h5')", "execution_count": 15, "outputs": []}, {"metadata": {}, "cell_type": "code", "source": "import numpy as np\nfrom tensorflow.keras.models import load_model\nfrom tensorflow.keras.preprocessing import image", "execution_count": 16, "outputs": []}, {"metadata": {}, "cell_type": "code", "source": "#load the model\nmodel=load_model('fruit.h5')", "execution_count": 17, "outputs": []}, {"metadata": {}, "cell_type": "code", "source": "pwd", "execution_count": 18, "outputs": [{"output_type": "execute_result", "execution_count": 18, "data": {"text/plain": "'/home/wsuser/work'"}, "metadata": {}}]}, {"metadata": {}, "cell_type": "code", "source": "ls", "execution_count": 19, "outputs": [{"output_type": "stream", "text": "\u001b[0m\u001b[01;34m'Dataset Plant Disease'\u001b[0m/   fruit.h5\r\n", "name": "stdout"}]}, {"metadata": {}, "cell_type": "code", "source": "img=image.load_img(r\"/home/wsuser/work/Dataset Plant Disease/fruit-dataset/fruit-dataset/test/Apple___healthy/00fca0da-2db3-481b-b98a-9b67bb7b105c___RS_HL 7708.jpg\")", "execution_count": 28, "outputs": [{"output_type": "error", "ename": "FileNotFoundError", "evalue": "[Errno 2] No such file or directory: '/home/wsuser/work/Dataset Plant Disease/fruit.h5/fruit-dataset/fruit-dataset/test/Apple___healthy/00fca0da-2db3-481b-b98a-9b67bb7b105c___RS_HL 7708.jpg'", "traceback": ["\u001b[0;31m---------------------------------------------------------------------------\u001b[0m", "\u001b[0;31mFileNotFoundError\u001b[0m                         Traceback (most recent call last)", "\u001b[0;32m/tmp/wsuser/ipykernel_280/1819606912.py\u001b[0m in \u001b[0;36m<module>\u001b[0;34m\u001b[0m\n\u001b[0;32m----> 1\u001b[0;31m \u001b[0mimg\u001b[0m\u001b[0;34m=\u001b[0m\u001b[0mimage\u001b[0m\u001b[0;34m.\u001b[0m\u001b[0mload_img\u001b[0m\u001b[0;34m(\u001b[0m\u001b[0;34mr\"/home/wsuser/work/Dataset Plant Disease/fruit.h5/fruit-dataset/fruit-dataset/test/Apple___healthy/00fca0da-2db3-481b-b98a-9b67bb7b105c___RS_HL 7708.jpg\"\u001b[0m\u001b[0;34m)\u001b[0m\u001b[0;34m\u001b[0m\u001b[0;34m\u001b[0m\u001b[0m\n\u001b[0m", "\u001b[0;32m/opt/conda/envs/Python-3.9/lib/python3.9/site-packages/keras/preprocessing/image.py\u001b[0m in \u001b[0;36mload_img\u001b[0;34m(path, grayscale, color_mode, target_size, interpolation)\u001b[0m\n\u001b[1;32m    311\u001b[0m       \u001b[0mValueError\u001b[0m\u001b[0;34m:\u001b[0m \u001b[0;32mif\u001b[0m \u001b[0minterpolation\u001b[0m \u001b[0mmethod\u001b[0m \u001b[0;32mis\u001b[0m \u001b[0;32mnot\u001b[0m \u001b[0msupported\u001b[0m\u001b[0;34m.\u001b[0m\u001b[0;34m\u001b[0m\u001b[0;34m\u001b[0m\u001b[0m\n\u001b[1;32m    312\u001b[0m   \"\"\"\n\u001b[0;32m--> 313\u001b[0;31m   return image.load_img(path, grayscale=grayscale, color_mode=color_mode,\n\u001b[0m\u001b[1;32m    314\u001b[0m                         target_size=target_size, interpolation=interpolation)\n\u001b[1;32m    315\u001b[0m \u001b[0;34m\u001b[0m\u001b[0m\n", "\u001b[0;32m/opt/conda/envs/Python-3.9/lib/python3.9/site-packages/keras_preprocessing/image/utils.py\u001b[0m in \u001b[0;36mload_img\u001b[0;34m(path, grayscale, color_mode, target_size, interpolation)\u001b[0m\n\u001b[1;32m    111\u001b[0m         raise ImportError('Could not import PIL.Image. '\n\u001b[1;32m    112\u001b[0m                           'The use of `load_img` requires PIL.')\n\u001b[0;32m--> 113\u001b[0;31m     \u001b[0;32mwith\u001b[0m \u001b[0mopen\u001b[0m\u001b[0;34m(\u001b[0m\u001b[0mpath\u001b[0m\u001b[0;34m,\u001b[0m \u001b[0;34m'rb'\u001b[0m\u001b[0;34m)\u001b[0m \u001b[0;32mas\u001b[0m \u001b[0mf\u001b[0m\u001b[0;34m:\u001b[0m\u001b[0;34m\u001b[0m\u001b[0;34m\u001b[0m\u001b[0m\n\u001b[0m\u001b[1;32m    114\u001b[0m         \u001b[0mimg\u001b[0m \u001b[0;34m=\u001b[0m \u001b[0mpil_image\u001b[0m\u001b[0;34m.\u001b[0m\u001b[0mopen\u001b[0m\u001b[0;34m(\u001b[0m\u001b[0mio\u001b[0m\u001b[0;34m.\u001b[0m\u001b[0mBytesIO\u001b[0m\u001b[0;34m(\u001b[0m\u001b[0mf\u001b[0m\u001b[0;34m.\u001b[0m\u001b[0mread\u001b[0m\u001b[0;34m(\u001b[0m\u001b[0;34m)\u001b[0m\u001b[0;34m)\u001b[0m\u001b[0;34m)\u001b[0m\u001b[0;34m\u001b[0m\u001b[0;34m\u001b[0m\u001b[0m\n\u001b[1;32m    115\u001b[0m         \u001b[0;32mif\u001b[0m \u001b[0mcolor_mode\u001b[0m \u001b[0;34m==\u001b[0m \u001b[0;34m'grayscale'\u001b[0m\u001b[0;34m:\u001b[0m\u001b[0;34m\u001b[0m\u001b[0;34m\u001b[0m\u001b[0m\n", "\u001b[0;31mFileNotFoundError\u001b[0m: [Errno 2] No such file or directory: '/home/wsuser/work/Dataset Plant Disease/fruit.h5/fruit-dataset/fruit-dataset/test/Apple___healthy/00fca0da-2db3-481b-b98a-9b67bb7b105c___RS_HL 7708.jpg'"]}]}, {"metadata": {}, "cell_type": "code", "source": "img=image.load_img(r\"/home/wsuser/work/Dataset Plant Disease/fruit-dataset/fruit-dataset/test/Apple__Black_rot/00e909aa-e3ae-4558-9961-336bb0f35db3___JR_FrgE.S 8593.jpg\")", "execution_count": 24, "outputs": [{"output_type": "error", "ename": "FileNotFoundError", "evalue": "[Errno 2] No such file or directory: \"/home/wsuser/work/'Dataset Plant Disease'/fruit-dataset/fruit-dataset/test/Apple__Black_rot/00e909aa-e3ae-4558-9961-336bb0f35db3___JR_FrgE.S 8593.jpg\"", "traceback": ["\u001b[0;31m---------------------------------------------------------------------------\u001b[0m", "\u001b[0;31mFileNotFoundError\u001b[0m                         Traceback (most recent call last)", "\u001b[0;32m/tmp/wsuser/ipykernel_280/2257741257.py\u001b[0m in \u001b[0;36m<module>\u001b[0;34m\u001b[0m\n\u001b[0;32m----> 1\u001b[0;31m \u001b[0mimg\u001b[0m\u001b[0;34m=\u001b[0m\u001b[0mimage\u001b[0m\u001b[0;34m.\u001b[0m\u001b[0mload_img\u001b[0m\u001b[0;34m(\u001b[0m\u001b[0;34mr\"/home/wsuser/work/'Dataset Plant Disease'/fruit-dataset/fruit-dataset/test/Apple__Black_rot/00e909aa-e3ae-4558-9961-336bb0f35db3___JR_FrgE.S 8593.jpg\"\u001b[0m\u001b[0;34m)\u001b[0m\u001b[0;34m\u001b[0m\u001b[0;34m\u001b[0m\u001b[0m\n\u001b[0m", "\u001b[0;32m/opt/conda/envs/Python-3.9/lib/python3.9/site-packages/keras/preprocessing/image.py\u001b[0m in \u001b[0;36mload_img\u001b[0;34m(path, grayscale, color_mode, target_size, interpolation)\u001b[0m\n\u001b[1;32m    311\u001b[0m       \u001b[0mValueError\u001b[0m\u001b[0;34m:\u001b[0m \u001b[0;32mif\u001b[0m \u001b[0minterpolation\u001b[0m \u001b[0mmethod\u001b[0m \u001b[0;32mis\u001b[0m \u001b[0;32mnot\u001b[0m \u001b[0msupported\u001b[0m\u001b[0;34m.\u001b[0m\u001b[0;34m\u001b[0m\u001b[0;34m\u001b[0m\u001b[0m\n\u001b[1;32m    312\u001b[0m   \"\"\"\n\u001b[0;32m--> 313\u001b[0;31m   return image.load_img(path, grayscale=grayscale, color_mode=color_mode,\n\u001b[0m\u001b[1;32m    314\u001b[0m                         target_size=target_size, interpolation=interpolation)\n\u001b[1;32m    315\u001b[0m \u001b[0;34m\u001b[0m\u001b[0m\n", "\u001b[0;32m/opt/conda/envs/Python-3.9/lib/python3.9/site-packages/keras_preprocessing/image/utils.py\u001b[0m in \u001b[0;36mload_img\u001b[0;34m(path, grayscale, color_mode, target_size, interpolation)\u001b[0m\n\u001b[1;32m    111\u001b[0m         raise ImportError('Could not import PIL.Image. '\n\u001b[1;32m    112\u001b[0m                           'The use of `load_img` requires PIL.')\n\u001b[0;32m--> 113\u001b[0;31m     \u001b[0;32mwith\u001b[0m \u001b[0mopen\u001b[0m\u001b[0;34m(\u001b[0m\u001b[0mpath\u001b[0m\u001b[0;34m,\u001b[0m \u001b[0;34m'rb'\u001b[0m\u001b[0;34m)\u001b[0m \u001b[0;32mas\u001b[0m \u001b[0mf\u001b[0m\u001b[0;34m:\u001b[0m\u001b[0;34m\u001b[0m\u001b[0;34m\u001b[0m\u001b[0m\n\u001b[0m\u001b[1;32m    114\u001b[0m         \u001b[0mimg\u001b[0m \u001b[0;34m=\u001b[0m \u001b[0mpil_image\u001b[0m\u001b[0;34m.\u001b[0m\u001b[0mopen\u001b[0m\u001b[0;34m(\u001b[0m\u001b[0mio\u001b[0m\u001b[0;34m.\u001b[0m\u001b[0mBytesIO\u001b[0m\u001b[0;34m(\u001b[0m\u001b[0mf\u001b[0m\u001b[0;34m.\u001b[0m\u001b[0mread\u001b[0m\u001b[0;34m(\u001b[0m\u001b[0;34m)\u001b[0m\u001b[0;34m)\u001b[0m\u001b[0;34m)\u001b[0m\u001b[0;34m\u001b[0m\u001b[0;34m\u001b[0m\u001b[0m\n\u001b[1;32m    115\u001b[0m         \u001b[0;32mif\u001b[0m \u001b[0mcolor_mode\u001b[0m \u001b[0;34m==\u001b[0m \u001b[0;34m'grayscale'\u001b[0m\u001b[0;34m:\u001b[0m\u001b[0;34m\u001b[0m\u001b[0;34m\u001b[0m\u001b[0m\n", "\u001b[0;31mFileNotFoundError\u001b[0m: [Errno 2] No such file or directory: \"/home/wsuser/work/'Dataset Plant Disease'/fruit-dataset/fruit-dataset/test/Apple__Black_rot/00e909aa-e3ae-4558-9961-336bb0f35db3___JR_FrgE.S 8593.jpg\""]}]}, {"metadata": {}, "cell_type": "code", "source": "img=image.load_img(r\"/home/wsuser/work/Dataset Plant Disease/fruit-dataset/fruit_dataset/test/Apple__Black_rot/00e909aa-e3ae-4558-9961-336bb0f35db3___JR_FrgE.S 8593.jpeg\")", "execution_count": 21, "outputs": [{"output_type": "error", "ename": "FileNotFoundError", "evalue": "[Errno 2] No such file or directory: '/home/wsuser/work/Dataset Plant Disease/fruit-dataset/fruit_dataset/test/Apple__Black_rot/00e909aa-e3ae-4558-9961-336bb0f35db3___JR_FrgE.S 8593.jpeg'", "traceback": ["\u001b[0;31m---------------------------------------------------------------------------\u001b[0m", "\u001b[0;31mFileNotFoundError\u001b[0m                         Traceback (most recent call last)", "\u001b[0;32m/tmp/wsuser/ipykernel_280/3422473068.py\u001b[0m in \u001b[0;36m<module>\u001b[0;34m\u001b[0m\n\u001b[0;32m----> 1\u001b[0;31m \u001b[0mimg\u001b[0m\u001b[0;34m=\u001b[0m\u001b[0mimage\u001b[0m\u001b[0;34m.\u001b[0m\u001b[0mload_img\u001b[0m\u001b[0;34m(\u001b[0m\u001b[0;34mr\"/home/wsuser/work/Dataset Plant Disease/fruit-dataset/fruit_dataset/test/Apple__Black_rot/00e909aa-e3ae-4558-9961-336bb0f35db3___JR_FrgE.S 8593.jpeg\"\u001b[0m\u001b[0;34m)\u001b[0m\u001b[0;34m\u001b[0m\u001b[0;34m\u001b[0m\u001b[0m\n\u001b[0m", "\u001b[0;32m/opt/conda/envs/Python-3.9/lib/python3.9/site-packages/keras/preprocessing/image.py\u001b[0m in \u001b[0;36mload_img\u001b[0;34m(path, grayscale, color_mode, target_size, interpolation)\u001b[0m\n\u001b[1;32m    311\u001b[0m       \u001b[0mValueError\u001b[0m\u001b[0;34m:\u001b[0m \u001b[0;32mif\u001b[0m \u001b[0minterpolation\u001b[0m \u001b[0mmethod\u001b[0m \u001b[0;32mis\u001b[0m \u001b[0;32mnot\u001b[0m \u001b[0msupported\u001b[0m\u001b[0;34m.\u001b[0m\u001b[0;34m\u001b[0m\u001b[0;34m\u001b[0m\u001b[0m\n\u001b[1;32m    312\u001b[0m   \"\"\"\n\u001b[0;32m--> 313\u001b[0;31m   return image.load_img(path, grayscale=grayscale, color_mode=color_mode,\n\u001b[0m\u001b[1;32m    314\u001b[0m                         target_size=target_size, interpolation=interpolation)\n\u001b[1;32m    315\u001b[0m \u001b[0;34m\u001b[0m\u001b[0m\n", "\u001b[0;32m/opt/conda/envs/Python-3.9/lib/python3.9/site-packages/keras_preprocessing/image/utils.py\u001b[0m in \u001b[0;36mload_img\u001b[0;34m(path, grayscale, color_mode, target_size, interpolation)\u001b[0m\n\u001b[1;32m    111\u001b[0m         raise ImportError('Could not import PIL.Image. '\n\u001b[1;32m    112\u001b[0m                           'The use of `load_img` requires PIL.')\n\u001b[0;32m--> 113\u001b[0;31m     \u001b[0;32mwith\u001b[0m \u001b[0mopen\u001b[0m\u001b[0;34m(\u001b[0m\u001b[0mpath\u001b[0m\u001b[0;34m,\u001b[0m \u001b[0;34m'rb'\u001b[0m\u001b[0;34m)\u001b[0m \u001b[0;32mas\u001b[0m \u001b[0mf\u001b[0m\u001b[0;34m:\u001b[0m\u001b[0;34m\u001b[0m\u001b[0;34m\u001b[0m\u001b[0m\n\u001b[0m\u001b[1;32m    114\u001b[0m         \u001b[0mimg\u001b[0m \u001b[0;34m=\u001b[0m \u001b[0mpil_image\u001b[0m\u001b[0;34m.\u001b[0m\u001b[0mopen\u001b[0m\u001b[0;34m(\u001b[0m\u001b[0mio\u001b[0m\u001b[0;34m.\u001b[0m\u001b[0mBytesIO\u001b[0m\u001b[0;34m(\u001b[0m\u001b[0mf\u001b[0m\u001b[0;34m.\u001b[0m\u001b[0mread\u001b[0m\u001b[0;34m(\u001b[0m\u001b[0;34m)\u001b[0m\u001b[0;34m)\u001b[0m\u001b[0;34m)\u001b[0m\u001b[0;34m\u001b[0m\u001b[0;34m\u001b[0m\u001b[0m\n\u001b[1;32m    115\u001b[0m         \u001b[0;32mif\u001b[0m \u001b[0mcolor_mode\u001b[0m \u001b[0;34m==\u001b[0m \u001b[0;34m'grayscale'\u001b[0m\u001b[0;34m:\u001b[0m\u001b[0;34m\u001b[0m\u001b[0;34m\u001b[0m\u001b[0m\n", "\u001b[0;31mFileNotFoundError\u001b[0m: [Errno 2] No such file or directory: '/home/wsuser/work/Dataset Plant Disease/fruit-dataset/fruit_dataset/test/Apple__Black_rot/00e909aa-e3ae-4558-9961-336bb0f35db3___JR_FrgE.S 8593.jpeg'"]}]}, {"metadata": {}, "cell_type": "code", "source": "", "execution_count": null, "outputs": []}, {"metadata": {}, "cell_type": "code", "source": "img", "execution_count": 22, "outputs": [{"output_type": "error", "ename": "NameError", "evalue": "name 'img' is not defined", "traceback": ["\u001b[0;31m---------------------------------------------------------------------------\u001b[0m", "\u001b[0;31mNameError\u001b[0m                                 Traceback (most recent call last)", "\u001b[0;32m/tmp/wsuser/ipykernel_280/2486947686.py\u001b[0m in \u001b[0;36m<module>\u001b[0;34m\u001b[0m\n\u001b[0;32m----> 1\u001b[0;31m \u001b[0mimg\u001b[0m\u001b[0;34m\u001b[0m\u001b[0;34m\u001b[0m\u001b[0m\n\u001b[0m", "\u001b[0;31mNameError\u001b[0m: name 'img' is not defined"]}]}, {"metadata": {}, "cell_type": "code", "source": "img=image.load_img(r\"/home/wsuser/work/Dataset Plant Disease/fruit-dataset/fruit-dataset/test/Apple___Black_rot/00e909aa-e3ae-4558-9961-336bb0f35db3___JR_FrgE.S 8593.jpeg\",target_size=(64,64))\nimg", "execution_count": 23, "outputs": [{"output_type": "error", "ename": "FileNotFoundError", "evalue": "[Errno 2] No such file or directory: '/home/wsuser/work/Dataset Plant Disease/fruit-dataset/fruit-dataset/test/Apple___Black_rot/00e909aa-e3ae-4558-9961-336bb0f35db3___JR_FrgE.S 8593.jpeg'", "traceback": ["\u001b[0;31m---------------------------------------------------------------------------\u001b[0m", "\u001b[0;31mFileNotFoundError\u001b[0m                         Traceback (most recent call last)", "\u001b[0;32m/tmp/wsuser/ipykernel_280/1293241842.py\u001b[0m in \u001b[0;36m<module>\u001b[0;34m\u001b[0m\n\u001b[0;32m----> 1\u001b[0;31m \u001b[0mimg\u001b[0m\u001b[0;34m=\u001b[0m\u001b[0mimage\u001b[0m\u001b[0;34m.\u001b[0m\u001b[0mload_img\u001b[0m\u001b[0;34m(\u001b[0m\u001b[0;34mr\"/home/wsuser/work/Dataset Plant Disease/fruit-dataset/fruit-dataset/test/Apple___Black_rot/00e909aa-e3ae-4558-9961-336bb0f35db3___JR_FrgE.S 8593.jpeg\"\u001b[0m\u001b[0;34m,\u001b[0m\u001b[0mtarget_size\u001b[0m\u001b[0;34m=\u001b[0m\u001b[0;34m(\u001b[0m\u001b[0;36m64\u001b[0m\u001b[0;34m,\u001b[0m\u001b[0;36m64\u001b[0m\u001b[0;34m)\u001b[0m\u001b[0;34m)\u001b[0m\u001b[0;34m\u001b[0m\u001b[0;34m\u001b[0m\u001b[0m\n\u001b[0m\u001b[1;32m      2\u001b[0m \u001b[0mimg\u001b[0m\u001b[0;34m\u001b[0m\u001b[0;34m\u001b[0m\u001b[0m\n", "\u001b[0;32m/opt/conda/envs/Python-3.9/lib/python3.9/site-packages/keras/preprocessing/image.py\u001b[0m in \u001b[0;36mload_img\u001b[0;34m(path, grayscale, color_mode, target_size, interpolation)\u001b[0m\n\u001b[1;32m    311\u001b[0m       \u001b[0mValueError\u001b[0m\u001b[0;34m:\u001b[0m \u001b[0;32mif\u001b[0m \u001b[0minterpolation\u001b[0m \u001b[0mmethod\u001b[0m \u001b[0;32mis\u001b[0m \u001b[0;32mnot\u001b[0m \u001b[0msupported\u001b[0m\u001b[0;34m.\u001b[0m\u001b[0;34m\u001b[0m\u001b[0;34m\u001b[0m\u001b[0m\n\u001b[1;32m    312\u001b[0m   \"\"\"\n\u001b[0;32m--> 313\u001b[0;31m   return image.load_img(path, grayscale=grayscale, color_mode=color_mode,\n\u001b[0m\u001b[1;32m    314\u001b[0m                         target_size=target_size, interpolation=interpolation)\n\u001b[1;32m    315\u001b[0m \u001b[0;34m\u001b[0m\u001b[0m\n", "\u001b[0;32m/opt/conda/envs/Python-3.9/lib/python3.9/site-packages/keras_preprocessing/image/utils.py\u001b[0m in \u001b[0;36mload_img\u001b[0;34m(path, grayscale, color_mode, target_size, interpolation)\u001b[0m\n\u001b[1;32m    111\u001b[0m         raise ImportError('Could not import PIL.Image. '\n\u001b[1;32m    112\u001b[0m                           'The use of `load_img` requires PIL.')\n\u001b[0;32m--> 113\u001b[0;31m     \u001b[0;32mwith\u001b[0m \u001b[0mopen\u001b[0m\u001b[0;34m(\u001b[0m\u001b[0mpath\u001b[0m\u001b[0;34m,\u001b[0m \u001b[0;34m'rb'\u001b[0m\u001b[0;34m)\u001b[0m \u001b[0;32mas\u001b[0m \u001b[0mf\u001b[0m\u001b[0;34m:\u001b[0m\u001b[0;34m\u001b[0m\u001b[0;34m\u001b[0m\u001b[0m\n\u001b[0m\u001b[1;32m    114\u001b[0m         \u001b[0mimg\u001b[0m \u001b[0;34m=\u001b[0m \u001b[0mpil_image\u001b[0m\u001b[0;34m.\u001b[0m\u001b[0mopen\u001b[0m\u001b[0;34m(\u001b[0m\u001b[0mio\u001b[0m\u001b[0;34m.\u001b[0m\u001b[0mBytesIO\u001b[0m\u001b[0;34m(\u001b[0m\u001b[0mf\u001b[0m\u001b[0;34m.\u001b[0m\u001b[0mread\u001b[0m\u001b[0;34m(\u001b[0m\u001b[0;34m)\u001b[0m\u001b[0;34m)\u001b[0m\u001b[0;34m)\u001b[0m\u001b[0;34m\u001b[0m\u001b[0;34m\u001b[0m\u001b[0m\n\u001b[1;32m    115\u001b[0m         \u001b[0;32mif\u001b[0m \u001b[0mcolor_mode\u001b[0m \u001b[0;34m==\u001b[0m \u001b[0;34m'grayscale'\u001b[0m\u001b[0;34m:\u001b[0m\u001b[0;34m\u001b[0m\u001b[0;34m\u001b[0m\u001b[0m\n", "\u001b[0;31mFileNotFoundError\u001b[0m: [Errno 2] No such file or directory: '/home/wsuser/work/Dataset Plant Disease/fruit-dataset/fruit-dataset/test/Apple___Black_rot/00e909aa-e3ae-4558-9961-336bb0f35db3___JR_FrgE.S 8593.jpeg'"]}]}, {"metadata": {}, "cell_type": "code", "source": "", "execution_count": null, "outputs": []}, {"metadata": {}, "cell_type": "code", "source": "", "execution_count": null, "outputs": []}], "metadata": {"kernelspec": {"name": "python3", "display_name": "Python 3.9", "language": "python"}, "language_info": {"name": "python", "version": "3.9.12", "mimetype": "text/x-python", "codemirror_mode": {"name": "ipython", "version": 3}, "pygments_lexer": "ipython3", "nbconvert_exporter": "python", "file_extension": ".py"}}, "nbformat": 4, "nbformat_minor": 1}